Traceback (most recent call last):
  File "D:\programowanie\python\projekt zespołowy\struktura\.venv\Lib\site-packages\wandb\sdk\wandb_config.py", line 162, in __getattr__
    return self.__getitem__(key)
           ^^^^^^^^^^^^^^^^^^^^^
  File "D:\programowanie\python\projekt zespołowy\struktura\.venv\Lib\site-packages\wandb\sdk\wandb_config.py", line 130, in __getitem__
    return self._items[key]
           ~~~~~~~~~~~^^^^^
KeyError: 'n_estimators'
The above exception was the direct cause of the following exception:
Traceback (most recent call last):
  File "D:\programowanie\python\projekt zespołowy\struktura\architectures\ml\RandomForest\train_RandomForest.py", line 20, in <module>
    train_RandomForest(wmii, sweep_config)
  File "D:\programowanie\python\projekt zespołowy\struktura\architectures\ml\RandomForest\train_RandomForest.py", line 11, in train_RandomForest
    clf = RandomForestClassifier(n_estimators=run.config.n_estimators, max_depth=run.config, random_state=42)
                                              ^^^^^^^^^^^^^^^^^^^^^^^
  File "D:\programowanie\python\projekt zespołowy\struktura\.venv\Lib\site-packages\wandb\sdk\wandb_config.py", line 164, in __getattr__
    raise AttributeError(
AttributeError: <class 'wandb.sdk.wandb_config.Config'> object has no attribute 'n_estimators'