Create sweep with ID: rn6jeza0
Sweep URL: https://wandb.ai/czarna-magia/your-project-name/sweeps/rn6jeza0
Traceback (most recent call last):
  File "D:\programowanie\python\projekt zespołowy\struktura\.venv\Lib\site-packages\wandb\sdk\wandb_config.py", line 162, in __getattr__
    return self.__getitem__(key)
           ^^^^^^^^^^^^^^^^^^^^^
  File "D:\programowanie\python\projekt zespołowy\struktura\.venv\Lib\site-packages\wandb\sdk\wandb_config.py", line 130, in __getitem__
    return self._items[key]
           ~~~~~~~~~~~^^^^^
KeyError: 'values'
The above exception was the direct cause of the following exception:
Traceback (most recent call last):
  File "D:\programowanie\python\projekt zespołowy\struktura\architectures\ml\RandomForest\train_RandomForest.py", line 14, in <module>
    train_ml_sweep(wmii, clf, sweep_config=sweep_config)
  File "D:\programowanie\python\projekt zespołowy\struktura\architectures\ml\train.py", line 64, in train_ml_sweep
    for parameters in wandb.config.values():
                      ^^^^^^^^^^^^^^^^^^^
  File "D:\programowanie\python\projekt zespołowy\struktura\.venv\Lib\site-packages\wandb\sdk\wandb_config.py", line 164, in __getattr__
    raise AttributeError(
AttributeError: <class 'wandb.sdk.wandb_config.Config'> object has no attribute 'values'