Traceback (most recent call last):
  File "D:\programowanie\python\projekt zespołowy\struktura\.venv\Lib\site-packages\wandb\sdk\wandb_config.py", line 162, in __getattr__
    return self.__getitem__(key)
           ^^^^^^^^^^^^^^^^^^^^^
  File "D:\programowanie\python\projekt zespołowy\struktura\.venv\Lib\site-packages\wandb\sdk\wandb_config.py", line 130, in __getitem__
    return self._items[key]
           ~~~~~~~~~~~^^^^^
KeyError: 'n_estimators'
The above exception was the direct cause of the following exception:
Traceback (most recent call last):
  File "D:\programowanie\python\projekt zespołowy\struktura\architectures\ml\RandomForest\train_RandomForest.py", line 43, in <module>
    train_RandomForest(wmii, sweep_config)
  File "D:\programowanie\python\projekt zespołowy\struktura\architectures\ml\RandomForest\train_RandomForest.py", line 20, in train_RandomForest
    n_estimators = config.n_estimators
                   ^^^^^^^^^^^^^^^^^^^
  File "D:\programowanie\python\projekt zespołowy\struktura\.venv\Lib\site-packages\wandb\sdk\wandb_config.py", line 164, in __getattr__
    raise AttributeError(
AttributeError: <class 'wandb.sdk.wandb_config.Config'> object has no attribute 'n_estimators'